Traceback (most recent call last):
  File "C:\Users\sebas\anaconda3\envs\jupyterbook\lib\site-packages\jupyter_cache\executors\utils.py", line 58, in single_nb_execution
    executenb(
  File "C:\Users\sebas\anaconda3\envs\jupyterbook\lib\site-packages\nbclient\client.py", line 1305, in execute
    return NotebookClient(nb=nb, resources=resources, km=km, **kwargs).execute()
  File "C:\Users\sebas\anaconda3\envs\jupyterbook\lib\site-packages\jupyter_core\utils\__init__.py", line 166, in wrapped
    return loop.run_until_complete(inner)
  File "C:\Users\sebas\anaconda3\envs\jupyterbook\lib\asyncio\base_events.py", line 647, in run_until_complete
    return future.result()
  File "C:\Users\sebas\anaconda3\envs\jupyterbook\lib\site-packages\nbclient\client.py", line 705, in async_execute
    await self.async_execute_cell(
  File "C:\Users\sebas\anaconda3\envs\jupyterbook\lib\site-packages\nbclient\client.py", line 1058, in async_execute_cell
    await self._check_raise_for_error(cell, cell_index, exec_reply)
  File "C:\Users\sebas\anaconda3\envs\jupyterbook\lib\site-packages\nbclient\client.py", line 914, in _check_raise_for_error
    raise CellExecutionError.from_cell_and_msg(cell, exec_reply_content)
nbclient.exceptions.CellExecutionError: An error occurred while executing the following cell:
------------------
fig = px.pie(data, values = 'track_popularity', names='playlist_genre', title='Popularity by genre', hole = 0.8)
fig.update_layout(showlegend=False, height = 600)
fig.update_traces(textposition = 'outside', textinfo='label+percent')
fig.show()

print( cut_bins.astype('category').cat.codes)
------------------


[1;31m---------------------------------------------------------------------------[0m
[1;31mNameError[0m                                 Traceback (most recent call last)
Cell [1;32mIn[3], line 6[0m
[0;32m      3[0m fig[38;5;241m.[39mupdate_traces(textposition [38;5;241m=[39m [38;5;124m'[39m[38;5;124moutside[39m[38;5;124m'[39m, textinfo[38;5;241m=[39m[38;5;124m'[39m[38;5;124mlabel+percent[39m[38;5;124m'[39m)
[0;32m      4[0m fig[38;5;241m.[39mshow()
[1;32m----> 6[0m [38;5;28mprint[39m( [43mcut_bins[49m[38;5;241m.[39mastype([38;5;124m'[39m[38;5;124mcategory[39m[38;5;124m'[39m)[38;5;241m.[39mcat[38;5;241m.[39mcodes)

[1;31mNameError[0m: name 'cut_bins' is not defined

