Traceback (most recent call last):
  File "C:\Users\sebas\anaconda3\envs\jupyterbook\lib\site-packages\jupyter_cache\executors\utils.py", line 58, in single_nb_execution
    executenb(
  File "C:\Users\sebas\anaconda3\envs\jupyterbook\lib\site-packages\nbclient\client.py", line 1305, in execute
    return NotebookClient(nb=nb, resources=resources, km=km, **kwargs).execute()
  File "C:\Users\sebas\anaconda3\envs\jupyterbook\lib\site-packages\jupyter_core\utils\__init__.py", line 166, in wrapped
    return loop.run_until_complete(inner)
  File "C:\Users\sebas\anaconda3\envs\jupyterbook\lib\asyncio\base_events.py", line 647, in run_until_complete
    return future.result()
  File "C:\Users\sebas\anaconda3\envs\jupyterbook\lib\site-packages\nbclient\client.py", line 705, in async_execute
    await self.async_execute_cell(
  File "C:\Users\sebas\anaconda3\envs\jupyterbook\lib\site-packages\nbclient\client.py", line 1058, in async_execute_cell
    await self._check_raise_for_error(cell, cell_index, exec_reply)
  File "C:\Users\sebas\anaconda3\envs\jupyterbook\lib\site-packages\nbclient\client.py", line 914, in _check_raise_for_error
    raise CellExecutionError.from_cell_and_msg(cell, exec_reply_content)
nbclient.exceptions.CellExecutionError: An error occurred while executing the following cell:
------------------
# Import the Dataset
data = pd.read_csv('spotify_songs.csv', sep = ',')

# Creating a second dataframe for popular tracks only
data_popular = data[data['track_popularity'] > 90]

def usable_date(dataframe):
    if dataframe.count('-') == 0:
        return dataframe + '01-01'
    else: return dataframe

# Create useable date
data[' = usable_date(data)   '] 
data['track_album_release_date'] = pd.to_datetime(data['track_album_release_date'], format = '%Y-%m-%d', dayfirst = True)
------------------


[1;31m---------------------------------------------------------------------------[0m
[1;31mKeyError[0m                                  Traceback (most recent call last)
File [1;32m~\anaconda3\envs\jupyterbook\lib\site-packages\pandas\core\indexes\base.py:3652[0m, in [0;36mIndex.get_loc[1;34m(self, key)[0m
[0;32m   3651[0m [38;5;28;01mtry[39;00m:
[1;32m-> 3652[0m     [38;5;28;01mreturn[39;00m [38;5;28;43mself[39;49m[38;5;241;43m.[39;49m[43m_engine[49m[38;5;241;43m.[39;49m[43mget_loc[49m[43m([49m[43mcasted_key[49m[43m)[49m
[0;32m   3653[0m [38;5;28;01mexcept[39;00m [38;5;167;01mKeyError[39;00m [38;5;28;01mas[39;00m err:

File [1;32m~\anaconda3\envs\jupyterbook\lib\site-packages\pandas\_libs\index.pyx:147[0m, in [0;36mpandas._libs.index.IndexEngine.get_loc[1;34m()[0m

File [1;32m~\anaconda3\envs\jupyterbook\lib\site-packages\pandas\_libs\index.pyx:176[0m, in [0;36mpandas._libs.index.IndexEngine.get_loc[1;34m()[0m

File [1;32mpandas\_libs\hashtable_class_helper.pxi:7080[0m, in [0;36mpandas._libs.hashtable.PyObjectHashTable.get_item[1;34m()[0m

File [1;32mpandas\_libs\hashtable_class_helper.pxi:7088[0m, in [0;36mpandas._libs.hashtable.PyObjectHashTable.get_item[1;34m()[0m

[1;31mKeyError[0m: ' = usable_date(data)   '

The above exception was the direct cause of the following exception:

[1;31mKeyError[0m                                  Traceback (most recent call last)
Cell [1;32mIn[2], line 13[0m
[0;32m     10[0m     [38;5;28;01melse[39;00m: [38;5;28;01mreturn[39;00m dataframe
[0;32m     12[0m [38;5;66;03m# Create useable date[39;00m
[1;32m---> 13[0m [43mdata[49m[43m[[49m[38;5;124;43m'[39;49m[38;5;124;43m = usable_date(data)   [39;49m[38;5;124;43m'[39;49m[43m][49m 
[0;32m     14[0m data[[38;5;124m'[39m[38;5;124mtrack_album_release_date[39m[38;5;124m'[39m] [38;5;241m=[39m pd[38;5;241m.[39mto_datetime(data[[38;5;124m'[39m[38;5;124mtrack_album_release_date[39m[38;5;124m'[39m], [38;5;28mformat[39m [38;5;241m=[39m [38;5;124m'[39m[38;5;124m%[39m[38;5;124mY-[39m[38;5;124m%[39m[38;5;124mm-[39m[38;5;132;01m%d[39;00m[38;5;124m'[39m, dayfirst [38;5;241m=[39m [38;5;28;01mTrue[39;00m)

File [1;32m~\anaconda3\envs\jupyterbook\lib\site-packages\pandas\core\frame.py:3761[0m, in [0;36mDataFrame.__getitem__[1;34m(self, key)[0m
[0;32m   3759[0m [38;5;28;01mif[39;00m [38;5;28mself[39m[38;5;241m.[39mcolumns[38;5;241m.[39mnlevels [38;5;241m>[39m [38;5;241m1[39m:
[0;32m   3760[0m     [38;5;28;01mreturn[39;00m [38;5;28mself[39m[38;5;241m.[39m_getitem_multilevel(key)
[1;32m-> 3761[0m indexer [38;5;241m=[39m [38;5;28;43mself[39;49m[38;5;241;43m.[39;49m[43mcolumns[49m[38;5;241;43m.[39;49m[43mget_loc[49m[43m([49m[43mkey[49m[43m)[49m
[0;32m   3762[0m [38;5;28;01mif[39;00m is_integer(indexer):
[0;32m   3763[0m     indexer [38;5;241m=[39m [indexer]

File [1;32m~\anaconda3\envs\jupyterbook\lib\site-packages\pandas\core\indexes\base.py:3654[0m, in [0;36mIndex.get_loc[1;34m(self, key)[0m
[0;32m   3652[0m     [38;5;28;01mreturn[39;00m [38;5;28mself[39m[38;5;241m.[39m_engine[38;5;241m.[39mget_loc(casted_key)
[0;32m   3653[0m [38;5;28;01mexcept[39;00m [38;5;167;01mKeyError[39;00m [38;5;28;01mas[39;00m err:
[1;32m-> 3654[0m     [38;5;28;01mraise[39;00m [38;5;167;01mKeyError[39;00m(key) [38;5;28;01mfrom[39;00m [38;5;21;01merr[39;00m
[0;32m   3655[0m [38;5;28;01mexcept[39;00m [38;5;167;01mTypeError[39;00m:
[0;32m   3656[0m     [38;5;66;03m# If we have a listlike key, _check_indexing_error will raise[39;00m
[0;32m   3657[0m     [38;5;66;03m#  InvalidIndexError. Otherwise we fall through and re-raise[39;00m
[0;32m   3658[0m     [38;5;66;03m#  the TypeError.[39;00m
[0;32m   3659[0m     [38;5;28mself[39m[38;5;241m.[39m_check_indexing_error(key)

[1;31mKeyError[0m: ' = usable_date(data)   '

