Traceback (most recent call last):
  File "C:\Users\sebas\anaconda3\envs\jupyterbook\lib\site-packages\jupyter_cache\executors\utils.py", line 58, in single_nb_execution
    executenb(
  File "C:\Users\sebas\anaconda3\envs\jupyterbook\lib\site-packages\nbclient\client.py", line 1305, in execute
    return NotebookClient(nb=nb, resources=resources, km=km, **kwargs).execute()
  File "C:\Users\sebas\anaconda3\envs\jupyterbook\lib\site-packages\jupyter_core\utils\__init__.py", line 166, in wrapped
    return loop.run_until_complete(inner)
  File "C:\Users\sebas\anaconda3\envs\jupyterbook\lib\asyncio\base_events.py", line 647, in run_until_complete
    return future.result()
  File "C:\Users\sebas\anaconda3\envs\jupyterbook\lib\site-packages\nbclient\client.py", line 705, in async_execute
    await self.async_execute_cell(
  File "C:\Users\sebas\anaconda3\envs\jupyterbook\lib\site-packages\nbclient\client.py", line 1058, in async_execute_cell
    await self._check_raise_for_error(cell, cell_index, exec_reply)
  File "C:\Users\sebas\anaconda3\envs\jupyterbook\lib\site-packages\nbclient\client.py", line 914, in _check_raise_for_error
    raise CellExecutionError.from_cell_and_msg(cell, exec_reply_content)
nbclient.exceptions.CellExecutionError: An error occurred while executing the following cell:
------------------
# Import the Dataset
data = pd.read_csv('spotify_songs.csv', sep = ',')
# Creating a second dataframe for popular tracks only
data_popular = data[data['track_popularity'] > 90]
# Create useable date
data['track_album_release_date'] = pd.to_datetime(data['track_album_release_date'])
------------------


[1;31m---------------------------------------------------------------------------[0m
[1;31mValueError[0m                                Traceback (most recent call last)
Cell [1;32mIn[2], line 6[0m
[0;32m      4[0m data_popular [38;5;241m=[39m data[data[[38;5;124m'[39m[38;5;124mtrack_popularity[39m[38;5;124m'[39m] [38;5;241m>[39m [38;5;241m90[39m]
[0;32m      5[0m [38;5;66;03m# Create useable date[39;00m
[1;32m----> 6[0m data[[38;5;124m'[39m[38;5;124mtrack_album_release_date[39m[38;5;124m'[39m] [38;5;241m=[39m [43mpd[49m[38;5;241;43m.[39;49m[43mto_datetime[49m[43m([49m[43mdata[49m[43m[[49m[38;5;124;43m'[39;49m[38;5;124;43mtrack_album_release_date[39;49m[38;5;124;43m'[39;49m[43m][49m[43m)[49m

File [1;32m~\anaconda3\envs\jupyterbook\lib\site-packages\pandas\core\tools\datetimes.py:1050[0m, in [0;36mto_datetime[1;34m(arg, errors, dayfirst, yearfirst, utc, format, exact, unit, infer_datetime_format, origin, cache)[0m
[0;32m   1048[0m         result [38;5;241m=[39m arg[38;5;241m.[39mmap(cache_array)
[0;32m   1049[0m     [38;5;28;01melse[39;00m:
[1;32m-> 1050[0m         values [38;5;241m=[39m [43mconvert_listlike[49m[43m([49m[43marg[49m[38;5;241;43m.[39;49m[43m_values[49m[43m,[49m[43m [49m[38;5;28;43mformat[39;49m[43m)[49m
[0;32m   1051[0m         result [38;5;241m=[39m arg[38;5;241m.[39m_constructor(values, index[38;5;241m=[39marg[38;5;241m.[39mindex, name[38;5;241m=[39marg[38;5;241m.[39mname)
[0;32m   1052[0m [38;5;28;01melif[39;00m [38;5;28misinstance[39m(arg, (ABCDataFrame, abc[38;5;241m.[39mMutableMapping)):

File [1;32m~\anaconda3\envs\jupyterbook\lib\site-packages\pandas\core\tools\datetimes.py:453[0m, in [0;36m_convert_listlike_datetimes[1;34m(arg, format, name, utc, unit, errors, dayfirst, yearfirst, exact)[0m
[0;32m    451[0m [38;5;66;03m# `format` could be inferred, or user didn't ask for mixed-format parsing.[39;00m
[0;32m    452[0m [38;5;28;01mif[39;00m [38;5;28mformat[39m [38;5;129;01mis[39;00m [38;5;129;01mnot[39;00m [38;5;28;01mNone[39;00m [38;5;129;01mand[39;00m [38;5;28mformat[39m [38;5;241m!=[39m [38;5;124m"[39m[38;5;124mmixed[39m[38;5;124m"[39m:
[1;32m--> 453[0m     [38;5;28;01mreturn[39;00m [43m_array_strptime_with_fallback[49m[43m([49m[43marg[49m[43m,[49m[43m [49m[43mname[49m[43m,[49m[43m [49m[43mutc[49m[43m,[49m[43m [49m[38;5;28;43mformat[39;49m[43m,[49m[43m [49m[43mexact[49m[43m,[49m[43m [49m[43merrors[49m[43m)[49m
[0;32m    455[0m result, tz_parsed [38;5;241m=[39m objects_to_datetime64ns(
[0;32m    456[0m     arg,
[0;32m    457[0m     dayfirst[38;5;241m=[39mdayfirst,
[1;32m   (...)[0m
[0;32m    461[0m     allow_object[38;5;241m=[39m[38;5;28;01mTrue[39;00m,
[0;32m    462[0m )
[0;32m    464[0m [38;5;28;01mif[39;00m tz_parsed [38;5;129;01mis[39;00m [38;5;129;01mnot[39;00m [38;5;28;01mNone[39;00m:
[0;32m    465[0m     [38;5;66;03m# We can take a shortcut since the datetime64 numpy array[39;00m
[0;32m    466[0m     [38;5;66;03m# is in UTC[39;00m

File [1;32m~\anaconda3\envs\jupyterbook\lib\site-packages\pandas\core\tools\datetimes.py:484[0m, in [0;36m_array_strptime_with_fallback[1;34m(arg, name, utc, fmt, exact, errors)[0m
[0;32m    473[0m [38;5;28;01mdef[39;00m [38;5;21m_array_strptime_with_fallback[39m(
[0;32m    474[0m     arg,
[0;32m    475[0m     name,
[1;32m   (...)[0m
[0;32m    479[0m     errors: [38;5;28mstr[39m,
[0;32m    480[0m ) [38;5;241m-[39m[38;5;241m>[39m Index:
[0;32m    481[0m [38;5;250m    [39m[38;5;124;03m"""[39;00m
[0;32m    482[0m [38;5;124;03m    Call array_strptime, with fallback behavior depending on 'errors'.[39;00m
[0;32m    483[0m [38;5;124;03m    """[39;00m
[1;32m--> 484[0m     result, timezones [38;5;241m=[39m [43marray_strptime[49m[43m([49m[43marg[49m[43m,[49m[43m [49m[43mfmt[49m[43m,[49m[43m [49m[43mexact[49m[38;5;241;43m=[39;49m[43mexact[49m[43m,[49m[43m [49m[43merrors[49m[38;5;241;43m=[39;49m[43merrors[49m[43m,[49m[43m [49m[43mutc[49m[38;5;241;43m=[39;49m[43mutc[49m[43m)[49m
[0;32m    485[0m     [38;5;28;01mif[39;00m [38;5;28many[39m(tz [38;5;129;01mis[39;00m [38;5;129;01mnot[39;00m [38;5;28;01mNone[39;00m [38;5;28;01mfor[39;00m tz [38;5;129;01min[39;00m timezones):
[0;32m    486[0m         [38;5;28;01mreturn[39;00m _return_parsed_timezone_results(result, timezones, utc, name)

File [1;32m~\anaconda3\envs\jupyterbook\lib\site-packages\pandas\_libs\tslibs\strptime.pyx:530[0m, in [0;36mpandas._libs.tslibs.strptime.array_strptime[1;34m()[0m

File [1;32m~\anaconda3\envs\jupyterbook\lib\site-packages\pandas\_libs\tslibs\strptime.pyx:351[0m, in [0;36mpandas._libs.tslibs.strptime.array_strptime[1;34m()[0m

[1;31mValueError[0m: time data "1981" doesn't match format "%Y-%m-%d", at position 25. You might want to try:
    - passing `format` if your strings have a consistent format;
    - passing `format='ISO8601'` if your strings are all ISO8601 but not necessarily in exactly the same format;
    - passing `format='mixed'`, and the format will be inferred for each element individually. You might want to use `dayfirst` alongside this.

